<mujoco model="biped_s4">
    <compiler angle="radian" />
    <size njmax="500" nconmax="100" />
    <asset>
        <mesh name="torso" file="torso.STL" />
        <mesh name="l_arm_pitch" file="l_arm_pitch.STL" />
        <mesh name="l_arm_roll" file="l_arm_roll.STL" />
        <mesh name="l_arm_yaw" file="l_arm_yaw.STL" />
        <mesh name="l_forearm_pitch" file="l_forearm_pitch.STL" />
        <mesh name="l_hand_yaw" file="l_hand_yaw.STL" />
        <mesh name="l_hand_pitch" file="l_hand_pitch.STL" />
        <mesh name="l_hand_roll" file="l_hand_roll.STL" />
        <mesh name="l_thumb_proximal_yaw" file="l_thumb_proximal_yaw.STL" />
        <mesh name="l_thumb_distal_pitch" file="l_thumb_distal_pitch.STL" />
        <mesh name="l_index_proximal_finger" file="l_index_proximal_finger.STL" />
        <mesh name="l_index_distal_finger" file="l_index_distal_finger.STL" />
        <mesh name="l_middle_proximal_finger" file="l_middle_proximal_finger.STL" />
        <mesh name="l_middle_distal_finger" file="l_middle_distal_finger.STL" />
        <mesh name="l_ring_proximal_finger" file="l_ring_proximal_finger.STL" />
        <mesh name="l_ring_distal_finger" file="l_ring_distal_finger.STL" />
        <mesh name="l_pinky_proximal_finger" file="l_pinky_proximal_finger.STL" />
        <mesh name="l_pinky_distal_finger" file="l_pinky_distal_finger.STL" />
        <mesh name="r_arm_pitch" file="r_arm_pitch.STL" />
        <mesh name="r_arm_roll" file="r_arm_roll.STL" />
        <mesh name="r_arm_yaw" file="r_arm_yaw.STL" />
        <mesh name="r_forearm_pitch" file="r_forearm_pitch.STL" />
        <mesh name="r_hand_yaw" file="r_hand_yaw.STL" />
        <mesh name="r_hand_pitch" file="r_hand_pitch.STL" />
        <mesh name="r_hand_roll" file="r_hand_roll.STL" />
        <mesh name="r_thumb_proximal_yaw" file="r_thumb_proximal_yaw.STL" />
        <mesh name="r_thumb_distal_pitch" file="r_thumb_distal_pitch.STL" />
        <mesh name="r_index_proximal_finger" file="r_index_proximal_finger.STL" />
        <mesh name="r_index_distal_finger" file="r_index_distal_finger.STL" />
        <mesh name="r_middle_proximal_finger" file="r_middle_proximal_finger.STL" />
        <mesh name="r_middle_distal_finger" file="r_middle_distal_finger.STL" />
        <mesh name="r_ring_proximal_finger" file="r_ring_proximal_finger.STL" />
        <mesh name="r_ring_distal_finger" file="r_ring_distal_finger.STL" />
        <mesh name="r_pinky_proximal_finger" file="r_pinky_proximal_finger.STL" />
        <mesh name="r_pinky_distal_finger" file="r_pinky_distal_finger.STL" />
        <mesh name="l_leg_roll" file="l_leg_roll.STL" />
        <mesh name="l_leg_yaw" file="l_leg_yaw.STL" />
        <mesh name="l_leg_pitch" file="l_leg_pitch.STL" />
        <mesh name="l_knee" file="l_knee.STL" />
        <mesh name="l_foot_pitch" file="l_foot_pitch.STL" />
        <mesh name="l_foot_roll" file="l_foot_roll.STL" />
        <mesh name="l_l_bar" file="l_l_bar.STL" />
        <mesh name="l_l_tendon" file="l_l_tendon.STL" />
        <mesh name="l_r_bar" file="l_r_bar.STL" />
        <mesh name="l_r_tendon" file="l_r_tendon.STL" />
        <mesh name="r_leg_roll" file="r_leg_roll.STL" />
        <mesh name="r_leg_yaw" file="r_leg_yaw.STL" />
        <mesh name="r_leg_pitch" file="r_leg_pitch.STL" />
        <mesh name="r_knee" file="r_knee.STL" />
        <mesh name="r_foot_pitch" file="r_foot_pitch.STL" />
        <mesh name="r_foot_roll" file="r_foot_roll.STL" />
        <mesh name="r_l_bar" file="r_l_bar.STL" />
        <mesh name="r_l_tendon" file="r_l_tendon.STL" />
        <mesh name="r_r_bar" file="r_r_bar.STL" />
        <mesh name="r_r_tendon" file="r_r_tendon.STL" />
        <mesh name="head_yaw" file="head_yaw.STL" />
        <mesh name="head_pitch" file="head_pitch.STL" />
    </asset>
    <worldbody>
        <geom type="mesh" rgba="1 1 1 1" mesh="torso" />
        <body name="l_arm_pitch" pos="-0.0175476 0.2547 0.3245">
            <inertial pos="0.0146835 -0.0166604 -6.82857e-05" quat="0.696586 0.712206 -0.0625859 -0.0601207" mass="0.165847" diaginertia="0.000271947 0.000196224 0.000121256" />
            <joint name="l_arm_pitch" pos="0 0 0" axis="0 1 0" limited="true" range="-3.14159 0.523599" />
            <geom type="mesh" rgba="1 1 1 1" mesh="l_arm_pitch" />
            <body name="l_arm_roll" pos="0 0 0">
                <inertial pos="0.0222873 0.0156946 -0.0202262" quat="0.398328 0.58059 0.26378 0.659295" mass="0.141427" diaginertia="0.000283338 0.000217951 0.000157462" />
                <joint name="l_arm_roll" pos="0 0 0" axis="1 0 0" limited="true" range="-0.349066 2.0944" />
                <geom type="mesh" rgba="1 1 1 1" mesh="l_arm_roll" />
                <body name="l_arm_yaw" pos="0 0 0">
                    <inertial pos="6.1694e-05 0.00525815 -0.128822" quat="0.237126 0.666158 0.237177 0.666147" mass="0.147794" diaginertia="9.38963e-05 7.96873e-05 7.00576e-05" />
                    <joint name="l_arm_yaw" pos="0 0 0" axis="0 0 1" limited="true" range="-1.5708 1.5708" />
                    <geom type="mesh" rgba="1 1 1 1" mesh="l_arm_yaw" />
                    <body name="l_forearm_pitch" pos="0 0 -0.1636">
                        <inertial pos="-1.42819e-05 0.00938314 -0.0522688" quat="0.632873 0.313955 0.634285 0.313985" mass="0.170165" diaginertia="0.00013362 0.000113739 9.55807e-05" />
                        <joint name="l_forearm_pitch" pos="0 0 0" axis="0 1 0" limited="true" range="-1.5708 0" />
                        <geom type="mesh" rgba="1 1 1 1" mesh="l_forearm_pitch" />
                        <body name="l_hand_yaw" pos="0 0 -0.13205">
                            <inertial pos="0.000113131 0.00969728 0.0227961" quat="0.493085 0.506908 0.492087 0.507703" mass="0.157336" diaginertia="0.000122264 8.44608e-05 7.64924e-05" />
                            <joint name="l_hand_yaw" pos="0 0 0" axis="0 0 1" limited="true" range="-1.5708 1.5708" />
                            <geom type="mesh" rgba="1 1 1 1" mesh="l_hand_yaw" />
                            <body name="l_hand_pitch" pos="0 0 0">
                                <inertial pos="0.0081061 0.00490163 -0.0527751" quat="0.972746 -0.202646 -0.0967872 0.0577326" mass="0.0853892" diaginertia="4.90153e-05 3.61802e-05 2.19136e-05" />
                                <joint name="l_hand_pitch" pos="0 0 0" axis="0 1 0" limited="true" range="-1.5708 1.5708" />
                                <geom type="mesh" rgba="1 1 1 1" mesh="l_hand_pitch" />
                                <body name="l_hand_roll" pos="0 0 -0.059">
                                    <inertial pos="0.00396051 0.00946265 -0.0666022" quat="0.394947 0.570359 0.314196 0.648066" mass="0.151353" diaginertia="0.000146582 0.000119118 9.05737e-05" />
                                    <joint name="l_hand_roll" pos="0 0 0" axis="1 0 0" limited="true" range="-1.5708 1.5708" />
                                    <geom type="mesh" rgba="1 1 1 1" mesh="l_hand_roll" />
                            
                                    <site name="attachment_site" pos="0 0.1 0" quat="-1 1 0 0"/>

                                    <body name="l_thumb_proximal_yaw" pos="0.025 -0.0216278 -0.1107">
                                        <inertial pos="0.00590167 -0.00373751 0.000119122" quat="0.600132 0.648007 0.296079 0.363683" mass="0.00177458" diaginertia="1.00106e-07 9.8657e-08 3.43995e-08" />
                                        <joint name="l_thumb_proximal_yaw" pos="0 0 0" axis="0 0 -1" limited="true" range="-3.14159 3.14159" />
                                        <geom type="mesh" rgba="1 1 1 0.25" mesh="l_thumb_proximal_yaw" />
                                        <body name="l_thumb_distal_pitch" pos="0.012 -0.0065 0">
                                            <inertial pos="0.00835401 -1.54981e-06 -0.0372051" quat="0.999868 -1.94083e-06 0.0162762 -0.000119228" mass="0.0143595" diaginertia="7.16051e-06 6.87911e-06 9.08132e-07" />
                                            <joint name="l_thumb_distal_pitch" pos="0 0 0" axis="0 1 0" limited="true" range="-3.14159 3.14159" />
                                            <geom type="mesh" rgba="1 1 1 1" mesh="l_thumb_distal_pitch" />
                                        </body>
                                    </body>
                                    <body name="l_index_proximal_finger" pos="0.0295025 0.00394879 -0.174731" quat="0.999879 0 -0.0155832 0">
                                        <inertial pos="0.000112678 0.00210468 -0.0171028" quat="0.724188 0.05274 -0.0554585 0.685343" mass="0.00213737" diaginertia="3.47926e-07 3.18535e-07 9.08141e-08" />
                                        <joint name="l_index_proximal_finger" pos="0 0 0" axis="-0.998506 0.0546396 0" limited="true" range="-3.14159 3.14159" />
                                        <geom type="mesh" rgba="1 1 1 1" mesh="l_index_proximal_finger" />
                                        <body name="l_index_distal_finger" pos="0.000133519 0.00243999 -0.0349146">
                                            <inertial pos="-8.804e-05 -0.00161951 -0.0254572" quat="0.726308 -0.0166814 0.0176103 0.686942" mass="0.00504466" diaginertia="7.81738e-07 7.63459e-07 1.138e-07" />
                                            <joint name="l_index_distal_finger" pos="0 0 0" axis="0.998506 -0.0546396 0" limited="true" range="-3.14159 3.14159" />
                                            <geom type="mesh" rgba="1 1 1 1" mesh="l_index_distal_finger" />
                                        </body>
                                    </body>
                                    <body name="l_middle_proximal_finger" pos="0.0085 0.00820382 -0.178435">
                                        <inertial pos="-8.42681e-08 0.0027021 -0.020783" quat="0.705466 0.0478411 -0.0478411 0.705507" mass="0.00260456" diaginertia="5.44468e-07 5.09608e-07 1.18037e-07" />
                                        <joint name="l_middle_proximal_finger" pos="0 0 0" axis="-1 0 0" limited="true" range="-3.14159 3.14159" />
                                        <geom type="mesh" rgba="1 1 1 1" mesh="l_middle_proximal_finger" />
                                        <body name="l_middle_distal_finger" pos="0 0.00292977 -0.0418977">
                                            <inertial pos="6.04649e-07 -0.00162351 -0.0254572" quat="0.707266 -0.0171778 0.0171703 0.70653" mass="0.00504467" diaginertia="7.81735e-07 7.63455e-07 1.13799e-07" />
                                            <joint name="l_middle_distal_finger" pos="0 0 0" axis="1 0 0" limited="true" range="-3.14159 3.14159" />
                                            <geom type="mesh" rgba="1 1 1 1" mesh="l_middle_distal_finger" />
                                        </body>
                                    </body>
                                    <body name="l_ring_proximal_finger" pos="-0.0126025 0.00807856 -0.176447" quat="0.999879 0 0.0155832 0">
                                        <inertial pos="-0.000147797 0.00269935 -0.0207828" quat="0.68592 0.0491526 -0.0465376 0.724522" mass="0.00260456" diaginertia="5.44468e-07 5.09608e-07 1.18037e-07" />
                                        <joint name="l_ring_proximal_finger" pos="0 0 0" axis="-0.998506 -0.0546396 0" limited="true" range="-3.14159 3.14159" />
                                        <geom type="mesh" rgba="1 1 1 1" mesh="l_ring_proximal_finger" />
                                        <body name="l_ring_distal_finger" pos="-0.000160223 0.00292799 -0.0418975">
                                            <inertial pos="-2.9782e-05 0.000551723 -0.0145821" quat="0.68743 -0.00980338 0.00928923 0.726125" mass="0.00182871" diaginertia="2.76151e-07 2.63479e-07 4.68186e-08" />
                                            <joint name="l_ring_distal_finger" pos="0 0 0" axis="0.998506 0.0546396 0" limited="true" range="-3.14159 3.14159" />
                                            <geom type="mesh" rgba="1 1 1 1" mesh="l_ring_distal_finger" />
                                        </body>
                                    </body>
                                    <body name="l_pinky_proximal_finger" pos="-0.0332309 0.00363387 -0.170227" quat="0.999456 0 0.0329919 0">
                                        <inertial pos="-0.000122637 0.00210213 -0.0171031" quat="0.684777 0.05571 -0.0523881 0.724729" mass="0.00213738" diaginertia="3.47927e-07 3.18535e-07 9.08146e-08" />
                                        <joint name="l_pinky_proximal_finger" pos="0 0 0" axis="-0.99837 -0.0570678 0" limited="true" range="-3.14159 3.14159" />
                                        <geom type="mesh" rgba="1 1 1 1" mesh="l_pinky_proximal_finger" />
                                        <body name="l_pinky_distal_finger" pos="-0.000139217 0.00243553 -0.0349149">
                                            <inertial pos="-2.37672e-05 0.000794235 -0.012715" quat="0.686968 -0.00436666 0.00172116 0.726672" mass="0.00162998" diaginertia="1.94746e-07 1.83819e-07 3.94562e-08" />
                                            <joint name="l_pinky_distal_finger" pos="0 0 0" axis="0.99837 0.0570678 0" limited="true" range="-3.14159 3.14159" />
                                            <geom type="mesh" rgba="1 1 1 1" mesh="l_pinky_distal_finger" />
                                        </body>
                                    </body>
                                </body>
                            </body>
                        </body>
                    </body>
                </body>
            </body>
        </body>
        <body name="r_arm_pitch" pos="-0.0175476 -0.2547 0.3245">
            <inertial pos="0.0146744 0.0168298 -8.16712e-05" quat="0.712375 0.696324 0.0605536 0.0631598" mass="0.165729" diaginertia="0.000271946 0.000196219 0.000121103" />
            <joint name="r_arm_pitch" pos="0 0 0" axis="0 1 0" limited="true" range="-3.14159 0.523599" />
            <geom type="mesh" rgba="1 1 1 1" mesh="r_arm_pitch" />
            <body name="r_arm_roll" pos="0 0 0">
                <inertial pos="0.0223009 -0.015695 -0.0202308" quat="0.65931 0.264022 0.580473 0.398313" mass="0.141494" diaginertia="0.000283519 0.000218099 0.000157689" />
                <joint name="r_arm_roll" pos="0 0 0" axis="1 0 0" limited="true" range="-2.0944 0.349066" />
                <geom type="mesh" rgba="1 1 1 1" mesh="r_arm_roll" />
                <body name="r_arm_yaw" pos="0 0 0">
                    <inertial pos="-4.82749e-05 -0.00525815 -0.128822" quat="-0.237177 0.666147 -0.237126 0.666158" mass="0.147794" diaginertia="9.38963e-05 7.96873e-05 7.00576e-05" />
                    <joint name="r_arm_yaw" pos="0 0 0" axis="0 0 1" limited="true" range="-1.5708 1.5708" />
                    <geom type="mesh" rgba="1 1 1 1" mesh="r_arm_yaw" />
                    <body name="r_forearm_pitch" pos="0 0 -0.1636">
                        <inertial pos="-0.000127233 -0.00951603 -0.0522688" quat="0.314696 0.632501 0.314725 0.633922" mass="0.170165" diaginertia="0.000133455 0.000113904 9.55807e-05" />
                        <joint name="r_forearm_pitch" pos="0 0 0" axis="0 1 0" limited="true" range="-1.5708 0" />
                        <geom type="mesh" rgba="1 1 1 1" mesh="r_forearm_pitch" />
                        <body name="r_hand_yaw" pos="0 0 -0.13205">
                            <inertial pos="-0.000112955 -0.0097445 0.0227958" quat="0.506916 0.49308 0.507696 0.492091" mass="0.157335" diaginertia="0.000122263 8.44602e-05 7.64922e-05" />
                            <joint name="r_hand_yaw" pos="0 0 0" axis="0 0 1" limited="true" range="-1.5708 1.5708" />
                            <geom type="mesh" rgba="1 1 1 1" mesh="r_hand_yaw" />
                            <body name="r_hand_pitch" pos="0 0 0">
                                <inertial pos="0.00735987 -0.00475238 -0.0529411" quat="0.97227 0.205866 -0.0962427 -0.0552063" mass="0.0853892" diaginertia="4.89785e-05 3.6108e-05 2.20226e-05" />
                                <joint name="r_hand_pitch" pos="0 0 0" axis="0 1 0" limited="true" range="-1.5708 1.5708" />
                                <geom type="mesh" rgba="1 1 1 1" mesh="r_hand_pitch" />
                                <body name="r_hand_roll" pos="0 0 -0.059">
                                    <inertial pos="0.00300068 -0.009483 -0.0665274" quat="0.648563 0.314072 0.569303 0.395751" mass="0.151513" diaginertia="0.000146677 0.000119257 9.06236e-05" />
                                    <joint name="r_hand_roll" pos="0 0 0" axis="1 0 0" limited="true" range="-1.5708 1.5708" />
                                    <geom type="mesh" rgba="1 1 1 1" mesh="r_hand_roll" />
                                    <body name="r_thumb_proximal_yaw" pos="0.0240163 0.0216278 -0.1107">
                                        <inertial pos="0.00590167 0.00373751 0.000280878" quat="0.296079 0.363683 0.600132 0.648007" mass="0.00177458" diaginertia="1.00106e-07 9.8657e-08 3.43995e-08" />
                                        <joint name="r_thumb_proximal_yaw" pos="0 0 0" axis="0 0 1" limited="true" range="-3.14159 3.14159" />
                                        <geom type="mesh" rgba="1 1 1 0.25" mesh="r_thumb_proximal_yaw" />
                                        <body name="r_thumb_distal_pitch" pos="0.012 0.0065 0.0004">
                                            <inertial pos="0.00835401 -1.55022e-06 -0.0372052" quat="0.999868 -1.94096e-06 0.0162762 -0.000119236" mass="0.0143595" diaginertia="7.16051e-06 6.87911e-06 9.08132e-07" />
                                            <joint name="r_thumb_distal_pitch" pos="0 0 0" axis="0 -1 0" limited="true" range="-3.14159 3.14159" />
                                            <geom type="mesh" rgba="1 1 1 1" mesh="r_thumb_distal_pitch" />
                                        </body>
                                    </body>
                                    <body name="r_index_proximal_finger" pos="0.0285188 -0.00394879 -0.174731" quat="0.999879 0 -0.0155832 0">
                                        <inertial pos="0.00011763 -0.00210444 -0.0171028" quat="0.685653 -0.055689 0.0524965 0.723894" mass="0.00213738" diaginertia="3.47927e-07 3.18535e-07 9.08146e-08" />
                                        <joint name="r_index_proximal_finger" pos="0 0 0" axis="0.998506 0.0546396 0" limited="true" range="-3.14159 3.14159" />
                                        <geom type="mesh" rgba="1 1 1 1" mesh="r_index_proximal_finger" />
                                        <body name="r_index_distal_finger" pos="0.000133519 -0.00243999 -0.0349146">
                                            <inertial pos="-8.92322e-05 0.00161947 -0.0254573" quat="0.687696 0.0176182 -0.0166735 0.725594" mass="0.00504466" diaginertia="7.81732e-07 7.63452e-07 1.13799e-07" />
                                            <joint name="r_index_distal_finger" pos="0 0 0" axis="-0.998506 -0.0546396 0" limited="true" range="-3.14159 3.14159" />
                                            <geom type="mesh" rgba="1 1 1 1" mesh="r_index_distal_finger" />
                                        </body>
                                    </body>
                                    <body name="r_middle_proximal_finger" pos="0.00751626 -0.00820382 -0.178435">
                                        <inertial pos="8.44814e-08 -0.0027021 -0.020783" quat="0.705466 -0.0478411 0.0478411 0.705507" mass="0.00260456" diaginertia="5.44468e-07 5.09608e-07 1.18037e-07" />
                                        <joint name="r_middle_proximal_finger" pos="0 0 0" axis="1 0 0" limited="true" range="-3.14159 3.14159" />
                                        <geom type="mesh" rgba="1 1 1 1" mesh="r_middle_proximal_finger" />
                                        <body name="r_middle_distal_finger" pos="0 -0.00292977 -0.0418977">
                                            <inertial pos="-6.04521e-07 0.00162351 -0.0254572" quat="0.707266 0.0171778 -0.0171703 0.70653" mass="0.00504467" diaginertia="7.81735e-07 7.63455e-07 1.13799e-07" />
                                            <joint name="r_middle_distal_finger" pos="0 0 0" axis="-1 0 0" limited="true" range="-3.14159 3.14159" />
                                            <geom type="mesh" rgba="1 1 1 1" mesh="r_middle_distal_finger" />
                                        </body>
                                    </body>
                                    <body name="r_ring_proximal_finger" pos="-0.0135863 -0.00807856 -0.176447" quat="0.999879 0 0.0155832 0">
                                        <inertial pos="-0.000147628 -0.00269936 -0.0207828" quat="0.724482 -0.0465377 0.0491525 0.685962" mass="0.00260456" diaginertia="5.44468e-07 5.09608e-07 1.18037e-07" />
                                        <joint name="r_ring_proximal_finger" pos="0 0 0" axis="0.998506 -0.0546396 0" limited="true" range="-3.14159 3.14159" />
                                        <geom type="mesh" rgba="1 1 1 1" mesh="r_ring_proximal_finger" />
                                        <body name="r_ring_distal_finger" pos="-0.000160223 -0.00292799 -0.0418975">
                                            <inertial pos="-3.05447e-05 -0.00055183 -0.0145819" quat="0.726055 0.00927821 -0.00980929 0.687504" mass="0.00182869" diaginertia="2.76147e-07 2.63473e-07 4.68174e-08" />
                                            <joint name="r_ring_distal_finger" pos="0 0 0" axis="-0.996567 -0.0546396 -0.0622018" limited="true" range="-3.14159 3.14159" />
                                            <geom type="mesh" rgba="1 1 1 1" mesh="r_ring_distal_finger" />
                                        </body>
                                    </body>
                                    <body name="r_pinky_proximal_finger" pos="-0.0342147 -0.00363387 -0.170227" quat="0.999456 0 0.0329919 0">
                                        <inertial pos="-0.000117693 -0.00210238 -0.0171031" quat="0.725022 -0.0526316 0.05548 0.684467" mass="0.00213737" diaginertia="3.47927e-07 3.18535e-07 9.08141e-08" />
                                        <joint name="r_pinky_proximal_finger" pos="0 0 0" axis="0.99837 -0.0570678 0" limited="true" range="-3.14159 3.14159" />
                                        <geom type="mesh" rgba="1 1 1 1" mesh="r_pinky_proximal_finger" />
                                        <body name="r_pinky_distal_finger" pos="-0.000139217 -0.00243553 -0.0349149">
                                            <inertial pos="-6.68864e-05 -0.000791925 -0.0127151" quat="0.727312 0.00425992 -0.00197281 0.686291" mass="0.00162994" diaginertia="1.94746e-07 1.83818e-07 3.94541e-08" />
                                            <joint name="r_pinky_distal_finger" pos="0 0 0" axis="-0.99837 0.0570678 0" limited="true" range="-3.14159 3.14159" />
                                            <geom type="mesh" rgba="1 1 1 1" mesh="r_pinky_distal_finger" />
                                        </body>
                                    </body>
                                </body>
                            </body>
                        </body>
                    </body>
                </body>
            </body>
        </body>
        <body name="l_leg_roll" pos="-0.00254758 0.087 -0.066">
            <inertial pos="-0.0111795 -0.000123217 -0.00147074" quat="0.000589532 0.698379 0.000560316 0.715727" mass="0.379426" diaginertia="0.000962034 0.000772105 0.000304348" />
            <joint name="l_leg_roll" pos="0 0 0" axis="-1 0 0" limited="true" range="-3.14159 3.14159" />
            <geom type="mesh" rgba="0.898039 0.917647 0.929412 1" mesh="l_leg_roll" />
            <body name="l_leg_yaw" pos="0 0 0">
                <inertial pos="-2.35778e-05 0.0577682 -0.103929" quat="0.70708 0.0157326 -0.0116372 0.706863" mass="1.02872" diaginertia="0.0022128 0.00147763 0.00129847" />
                <joint name="l_leg_yaw" pos="0 0 0" axis="0 0 1" limited="true" range="-3.14159 3.14159" />
                <geom type="mesh" rgba="1 1 1 1" mesh="l_leg_yaw" />
                <body name="l_leg_pitch" pos="0 0.02545 -0.12345">
                    <inertial pos="-0.00116946 -0.0111798 -0.100922" quat="0.660252 -0.00737768 -0.0101843 0.750939" mass="2.07734" diaginertia="0.00803373 0.00753625 0.00365508" />
                    <joint name="l_leg_pitch" pos="0 0 0" axis="0 1 0" limited="true" range="-3.14159 3.14159" />
                    <geom type="mesh" rgba="0.898039 0.917647 0.929412 1" mesh="l_leg_pitch" />
                    <body name="l_knee" pos="-0.0103902 0 -0.249784">
                        <inertial pos="0.00837416 -1.38261e-05 -0.140327" quat="0.728713 0.0140368 0.00867859 0.68462" mass="1.44549" diaginertia="0.0112847 0.0110375 0.000846397" />
                        <joint name="l_knee" pos="0 0 0" axis="0 1 0" limited="true" range="-3.14159 3.14159" />
                        <geom type="mesh" rgba="0.898039 0.917647 0.929412 1" mesh="l_knee" />
                        <body name="l_foot_pitch" pos="0 0 -0.346">
                            <inertial pos="-1.81202e-07 1.81203e-07 0" quat="-2.63135e-05 0.70708 -2.63115e-05 0.707134" mass="0.00680557" diaginertia="9.09837e-07 5.13627e-07 5.13627e-07" />
                            <joint name="l_foot_pitch" pos="0 0 0" axis="0 1 0" limited="true" range="-3.14159 3.14159" />
                            <geom type="mesh" rgba="1 1 1 1" mesh="l_foot_pitch" />
                            <body name="l_foot_roll" pos="0 0 0">
                                <inertial pos="0.00986619 -8.14594e-06 -0.0323277" quat="4.90642e-05 0.711579 -2.19789e-05 0.702606" mass="0.191216" diaginertia="0.000418071 0.000315195 0.000129528" />
                                <joint name="l_foot_roll" pos="0 0 0" axis="-1 0 0" limited="true" range="-3.14159 3.14159" />
                                <geom type="mesh" rgba="1 1 1 1" mesh="l_foot_roll" />
                            </body>
                        </body>
                        <body name="l_l_bar" pos="0 0.026 -0.09">
                            <inertial pos="-0.0172817 0.00661594 -2.76945e-06" quat="0.468554 0.468501 0.529578 0.529633" mass="0.0241949" diaginertia="1.65444e-05 1.40553e-05 2.82353e-06" />
                            <joint name="l_l_bar" pos="0 0 0" axis="0 1 0" limited="true" range="-3.14159 3.14159" />
                            <geom type="mesh" rgba="0.898039 0.917647 0.929412 1" mesh="l_l_bar" />
                            <body name="l_l_tendon" pos="-0.058 0 0">
                                <inertial pos="0.000909568 -0.00107383 -0.116412" quat="0.999992 -0.000202341 -0.00390635 -2.81587e-06" mass="0.0723259" diaginertia="0.000407066 0.000405861 2.46497e-06" />
                                <joint name="l_l_tendon" pos="0 0 0" axis="0 -1 0" limited="true" range="-3.14159 3.14159" />
                                <geom type="mesh" rgba="0.898039 0.917647 0.929412 1" mesh="l_l_tendon" />
                            </body>
                        </body>
                        <body name="l_r_bar" pos="0 -0.026 -0.153">
                            <inertial pos="-0.0172817 -0.00661594 -2.64615e-06" quat="0.529652 0.529559 0.468471 0.468584" mass="0.0241949" diaginertia="1.65444e-05 1.40553e-05 2.82353e-06" />
                            <joint name="l_r_bar" pos="0 0 0" axis="0 1 0" limited="true" range="-3.14159 3.14159" />
                            <geom type="mesh" rgba="0.898039 0.917647 0.929412 1" mesh="l_r_bar" />
                            <body name="l_r_tendon" pos="-0.058 0 -1.0363e-05">
                                <inertial pos="0.000886522 0.00109368 -0.0855353" quat="0.999987 0.00034244 -0.00518158 4.68862e-06" mass="0.0569965" diaginertia="0.000181318 0.000180445 1.9542e-06" />
                                <joint name="l_r_tendon" pos="0 0 0" axis="0 1 0" limited="true" range="-3.14159 3.14159" />
                                <geom type="mesh" rgba="0.898039 0.917647 0.929412 1" mesh="l_r_tendon" />
                            </body>
                        </body>
                    </body>
                </body>
            </body>
        </body>
        <body name="r_leg_roll" pos="-0.00254758 -0.087 -0.066">
            <inertial pos="-0.0111795 -0.000123217 -0.00147074" quat="0.000589532 0.698379 0.000560316 0.715727" mass="0.379426" diaginertia="0.000962034 0.000772105 0.000304348" />
            <joint name="r_leg_roll" pos="0 0 0" axis="-1 0 0" limited="true" range="-3.14159 3.14159" />
            <geom type="mesh" rgba="0.898039 0.917647 0.929412 1" mesh="r_leg_roll" />
            <body name="r_leg_yaw" pos="0 0 0">
                <inertial pos="2.35778e-05 -0.0577682 -0.103929" quat="0.70708 -0.0157326 0.0116372 0.706863" mass="1.02872" diaginertia="0.0022128 0.00147763 0.00129847" />
                <joint name="r_leg_yaw" pos="0 0 0" axis="0 0 1" limited="true" range="-3.14159 3.14159" />
                <geom type="mesh" rgba="0.898039 0.917647 0.929412 1" mesh="r_leg_yaw" />
                <body name="r_leg_pitch" pos="0 -0.02545 -0.12345">
                    <inertial pos="-0.00107075 0.0113653 -0.100928" quat="0.749509 -0.010143 -0.00787285 0.66187" mass="2.07086" diaginertia="0.0080412 0.00754295 0.00366032" />
                    <joint name="r_leg_pitch" pos="0 0 0" axis="0 -1 0" limited="true" range="-3.14159 3.14159" />
                    <geom type="mesh" rgba="0.898039 0.917647 0.929412 1" mesh="r_leg_pitch" />
                    <body name="r_knee" pos="-0.0103902 0 -0.249784">
                        <inertial pos="0.00837373 1.48732e-05 -0.140326" quat="0.684621 0.00867717 0.0140374 0.728712" mass="1.44559" diaginertia="0.011285 0.0110378 0.000846443" />
                        <joint name="r_knee" pos="0 0 0" axis="0 1 0" limited="true" range="-3.14159 3.14159" />
                        <geom type="mesh" rgba="0.898039 0.917647 0.929412 1" mesh="r_knee" />
                        <body name="r_foot_pitch" pos="0 0 -0.346">
                            <inertial pos="-1.81203e-07 -1.81203e-07 0" quat="0.5 0.500038 -0.5 0.499962" mass="0.00680557" diaginertia="9.09837e-07 5.13627e-07 5.13627e-07" />
                            <joint name="r_foot_pitch" pos="0 0 0" axis="0 1 0" limited="true" range="-3.14159 3.14159" />
                            <geom type="mesh" rgba="1 1 1 1" mesh="r_foot_pitch" />
                            <body name="r_foot_roll" pos="0 0 0">
                                <inertial pos="0.00986619 -8.14594e-06 -0.0323277" quat="4.90642e-05 0.711579 -2.19789e-05 0.702606" mass="0.191216" diaginertia="0.000418071 0.000315195 0.000129528" />
                                <joint name="r_foot_roll" pos="0 0 0" axis="-1 0 0" limited="true" range="-3.14159 3.14159" />
                                <geom type="mesh" rgba="1 1 1 1" mesh="r_foot_roll" />
                            </body>
                        </body>
                        <body name="r_l_bar" pos="0 0.026 -0.153">
                            <inertial pos="-0.0172817 0.00661593 -2.6266e-06" quat="0.468584 0.468471 0.529559 0.529652" mass="0.0241949" diaginertia="1.65443e-05 1.40553e-05 2.82352e-06" />
                            <joint name="r_l_bar" pos="0 0 0" axis="0 -1 0" limited="true" range="-3.14159 3.14159" />
                            <geom type="mesh" rgba="1 1 1 1" mesh="r_l_bar" />
                            <body name="r_l_tendon" pos="-0.058 0 -1.0363e-05">
                                <inertial pos="0.000886325 -0.00109368 -0.0855353" quat="0.999987 -0.00034247 -0.00518125 1.13021e-06" mass="0.0569965" diaginertia="0.000181318 0.000180445 1.9542e-06" />
                                <joint name="r_l_tendon" pos="0 0 0" axis="0 -1 0" limited="true" range="-3.14159 3.14159" />
                                <geom type="mesh" rgba="0.898039 0.917647 0.929412 1" mesh="r_l_tendon" />
                            </body>
                        </body>
                        <body name="r_r_bar" pos="0 -0.026 -0.09">
                            <inertial pos="-0.0172817 -0.00661593 -2.78901e-06" quat="0.529633 0.529578 0.468501 0.468554" mass="0.0241949" diaginertia="1.65443e-05 1.40553e-05 2.82352e-06" />
                            <joint name="r_r_bar" pos="0 0 0" axis="0 -1 0" limited="true" range="-3.14159 3.14159" />
                            <geom type="mesh" rgba="1 1 1 1" mesh="r_r_bar" />
                            <body name="r_r_tendon" pos="-0.058 0 0">
                                <inertial pos="0.000909569 0.00107383 -0.116412" quat="0.999992 0.000202341 -0.00390635 2.82809e-06" mass="0.0723259" diaginertia="0.000407066 0.000405861 2.46497e-06" />
                                <joint name="r_r_tendon" pos="0 0 0" axis="0 1 0" limited="true" range="-3.14159 3.14159" />
                                <geom type="mesh" rgba="0.898039 0.917647 0.929412 1" mesh="r_r_tendon" />
                            </body>
                        </body>
                    </body>
                </body>
            </body>
        </body>
        <body name="head_yaw" pos="-0.0175476 0 0.4994">
            <inertial pos="-0.000116066 0.00341283 -0.00762228" quat="0.690012 -0.14552 0.0856302 0.703829" mass="0.0876587" diaginertia="8.01488e-05 5.29402e-05 4.99293e-05" />
            <joint name="head_yaw" pos="0 0 0" axis="0 0 -1" limited="true" range="-3.14159 3.14159" />
            <geom type="mesh" rgba="1 1 1 1" mesh="head_yaw" />
            <body name="head_pitch" pos="0 0 0">
                <inertial pos="0.0108077 -0.00100495 0.0523166" quat="0.00733068 0.883186 -0.0143617 0.468746" mass="0.348142" diaginertia="0.00134031 0.000957631 0.000704232" />
                <joint name="head_pitch" pos="0 0 0" axis="0 1 0" limited="true" range="-3.14159 3.14159" />
                <geom type="mesh" rgba="1 1 1 1" mesh="head_pitch" />
            </body>
        </body>
    </worldbody>
</mujoco>
